[2021-11-16 12:30:46 +0000] [5353] [INFO] Starting gunicorn 20.1.0
[2021-11-16 12:30:46 +0000] [5353] [INFO] Listening at: http://0.0.0.0:8000 (5353)
[2021-11-16 12:30:46 +0000] [5353] [INFO] Using worker: sync
[2021-11-16 12:30:46 +0000] [5354] [INFO] Booting worker with pid: 5354
[2021-11-16 12:30:46 +0000] [5354] [ERROR] Exception in worker process
Traceback (most recent call last):
  File "/home/ubuntu/miniconda3/envs/humanscape/lib/python3.9/site-packages/gunicorn/arbiter.py", line 589, in spawn_worker
    worker.init_process()
  File "/home/ubuntu/miniconda3/envs/humanscape/lib/python3.9/site-packages/gunicorn/workers/base.py", line 134, in init_process
    self.load_wsgi()
  File "/home/ubuntu/miniconda3/envs/humanscape/lib/python3.9/site-packages/gunicorn/workers/base.py", line 146, in load_wsgi
    self.wsgi = self.app.wsgi()
  File "/home/ubuntu/miniconda3/envs/humanscape/lib/python3.9/site-packages/gunicorn/app/base.py", line 67, in wsgi
    self.callable = self.load()
  File "/home/ubuntu/miniconda3/envs/humanscape/lib/python3.9/site-packages/gunicorn/app/wsgiapp.py", line 58, in load
    return self.load_wsgiapp()
  File "/home/ubuntu/miniconda3/envs/humanscape/lib/python3.9/site-packages/gunicorn/app/wsgiapp.py", line 48, in load_wsgiapp
    return util.import_app(self.app_uri)
  File "/home/ubuntu/miniconda3/envs/humanscape/lib/python3.9/site-packages/gunicorn/util.py", line 359, in import_app
    mod = importlib.import_module(module)
  File "/home/ubuntu/miniconda3/envs/humanscape/lib/python3.9/importlib/__init__.py", line 127, in import_module
    return _bootstrap._gcd_import(name[level:], package, level)
  File "<frozen importlib._bootstrap>", line 1030, in _gcd_import
  File "<frozen importlib._bootstrap>", line 1007, in _find_and_load
  File "<frozen importlib._bootstrap>", line 972, in _find_and_load_unlocked
  File "<frozen importlib._bootstrap>", line 228, in _call_with_frames_removed
  File "<frozen importlib._bootstrap>", line 1030, in _gcd_import
  File "<frozen importlib._bootstrap>", line 1007, in _find_and_load
  File "<frozen importlib._bootstrap>", line 984, in _find_and_load_unlocked
ModuleNotFoundError: No module named 'app_name'
[2021-11-16 12:30:46 +0000] [5354] [INFO] Worker exiting (pid: 5354)
[2021-11-16 12:30:46 +0000] [5353] [INFO] Shutting down: Master
[2021-11-16 12:30:46 +0000] [5353] [INFO] Reason: Worker failed to boot.
[2021-11-16 12:33:45 +0000] [5372] [INFO] Starting gunicorn 20.1.0
[2021-11-16 12:33:45 +0000] [5372] [INFO] Listening at: http://0.0.0.0:8000 (5372)
[2021-11-16 12:33:45 +0000] [5372] [INFO] Using worker: sync
[2021-11-16 12:33:45 +0000] [5373] [INFO] Booting worker with pid: 5373
[2021-11-16 12:33:45 +0000] [5373] [ERROR] Exception in worker process
Traceback (most recent call last):
  File "/home/ubuntu/miniconda3/envs/humanscape/lib/python3.9/site-packages/gunicorn/arbiter.py", line 589, in spawn_worker
    worker.init_process()
  File "/home/ubuntu/miniconda3/envs/humanscape/lib/python3.9/site-packages/gunicorn/workers/base.py", line 134, in init_process
    self.load_wsgi()
  File "/home/ubuntu/miniconda3/envs/humanscape/lib/python3.9/site-packages/gunicorn/workers/base.py", line 146, in load_wsgi
    self.wsgi = self.app.wsgi()
  File "/home/ubuntu/miniconda3/envs/humanscape/lib/python3.9/site-packages/gunicorn/app/base.py", line 67, in wsgi
    self.callable = self.load()
  File "/home/ubuntu/miniconda3/envs/humanscape/lib/python3.9/site-packages/gunicorn/app/wsgiapp.py", line 58, in load
    return self.load_wsgiapp()
  File "/home/ubuntu/miniconda3/envs/humanscape/lib/python3.9/site-packages/gunicorn/app/wsgiapp.py", line 48, in load_wsgiapp
    return util.import_app(self.app_uri)
  File "/home/ubuntu/miniconda3/envs/humanscape/lib/python3.9/site-packages/gunicorn/util.py", line 359, in import_app
    mod = importlib.import_module(module)
  File "/home/ubuntu/miniconda3/envs/humanscape/lib/python3.9/importlib/__init__.py", line 127, in import_module
    return _bootstrap._gcd_import(name[level:], package, level)
  File "<frozen importlib._bootstrap>", line 1030, in _gcd_import
  File "<frozen importlib._bootstrap>", line 1007, in _find_and_load
  File "<frozen importlib._bootstrap>", line 972, in _find_and_load_unlocked
  File "<frozen importlib._bootstrap>", line 228, in _call_with_frames_removed
  File "<frozen importlib._bootstrap>", line 1030, in _gcd_import
  File "<frozen importlib._bootstrap>", line 1007, in _find_and_load
  File "<frozen importlib._bootstrap>", line 984, in _find_and_load_unlocked
ModuleNotFoundError: No module named 'app_name'
[2021-11-16 12:33:45 +0000] [5373] [INFO] Worker exiting (pid: 5373)
[2021-11-16 12:33:45 +0000] [5372] [INFO] Shutting down: Master
[2021-11-16 12:33:45 +0000] [5372] [INFO] Reason: Worker failed to boot.
[2021-11-16 12:37:42 +0000] [5380] [INFO] Starting gunicorn 20.1.0
[2021-11-16 12:37:42 +0000] [5380] [INFO] Listening at: http://0.0.0.0:8000 (5380)
[2021-11-16 12:37:42 +0000] [5380] [INFO] Using worker: sync
[2021-11-16 12:37:42 +0000] [5381] [INFO] Booting worker with pid: 5381
Internal Server Error: /clinics/C130010
Traceback (most recent call last):
  File "/home/ubuntu/miniconda3/envs/humanscape/lib/python3.9/site-packages/django/db/backends/utils.py", line 84, in _execute
    return self.cursor.execute(sql, params)
  File "/home/ubuntu/miniconda3/envs/humanscape/lib/python3.9/site-packages/django/db/backends/sqlite3/base.py", line 423, in execute
    return Database.Cursor.execute(self, query, params)
sqlite3.OperationalError: no such table: clinics

The above exception was the direct cause of the following exception:

Traceback (most recent call last):
  File "/home/ubuntu/miniconda3/envs/humanscape/lib/python3.9/site-packages/django/core/handlers/exception.py", line 47, in inner
    response = get_response(request)
  File "/home/ubuntu/miniconda3/envs/humanscape/lib/python3.9/site-packages/django/core/handlers/base.py", line 181, in _get_response
    response = wrapped_callback(request, *callback_args, **callback_kwargs)
  File "/home/ubuntu/miniconda3/envs/humanscape/lib/python3.9/site-packages/django/views/generic/base.py", line 70, in view
    return self.dispatch(request, *args, **kwargs)
  File "/home/ubuntu/miniconda3/envs/humanscape/lib/python3.9/site-packages/django/views/generic/base.py", line 98, in dispatch
    return handler(request, *args, **kwargs)
  File "/home/ubuntu/human-scape-InfinityLoop/clinics/views.py", line 10, in get
    clinic = Clinic.objects.get(id=clinic_id)
  File "/home/ubuntu/miniconda3/envs/humanscape/lib/python3.9/site-packages/django/db/models/manager.py", line 85, in manager_method
    return getattr(self.get_queryset(), name)(*args, **kwargs)
  File "/home/ubuntu/miniconda3/envs/humanscape/lib/python3.9/site-packages/django/db/models/query.py", line 431, in get
    num = len(clone)
  File "/home/ubuntu/miniconda3/envs/humanscape/lib/python3.9/site-packages/django/db/models/query.py", line 262, in __len__
    self._fetch_all()
  File "/home/ubuntu/miniconda3/envs/humanscape/lib/python3.9/site-packages/django/db/models/query.py", line 1324, in _fetch_all
    self._result_cache = list(self._iterable_class(self))
  File "/home/ubuntu/miniconda3/envs/humanscape/lib/python3.9/site-packages/django/db/models/query.py", line 51, in __iter__
    results = compiler.execute_sql(chunked_fetch=self.chunked_fetch, chunk_size=self.chunk_size)
  File "/home/ubuntu/miniconda3/envs/humanscape/lib/python3.9/site-packages/django/db/models/sql/compiler.py", line 1175, in execute_sql
    cursor.execute(sql, params)
  File "/home/ubuntu/miniconda3/envs/humanscape/lib/python3.9/site-packages/django/db/backends/utils.py", line 98, in execute
    return super().execute(sql, params)
  File "/home/ubuntu/miniconda3/envs/humanscape/lib/python3.9/site-packages/django/db/backends/utils.py", line 66, in execute
    return self._execute_with_wrappers(sql, params, many=False, executor=self._execute)
  File "/home/ubuntu/miniconda3/envs/humanscape/lib/python3.9/site-packages/django/db/backends/utils.py", line 75, in _execute_with_wrappers
    return executor(sql, params, many, context)
  File "/home/ubuntu/miniconda3/envs/humanscape/lib/python3.9/site-packages/django/db/backends/utils.py", line 84, in _execute
    return self.cursor.execute(sql, params)
  File "/home/ubuntu/miniconda3/envs/humanscape/lib/python3.9/site-packages/django/db/utils.py", line 90, in __exit__
    raise dj_exc_value.with_traceback(traceback) from exc_value
  File "/home/ubuntu/miniconda3/envs/humanscape/lib/python3.9/site-packages/django/db/backends/utils.py", line 84, in _execute
    return self.cursor.execute(sql, params)
  File "/home/ubuntu/miniconda3/envs/humanscape/lib/python3.9/site-packages/django/db/backends/sqlite3/base.py", line 423, in execute
    return Database.Cursor.execute(self, query, params)
django.db.utils.OperationalError: no such table: clinics
Internal Server Error: /clinics/C13001
Traceback (most recent call last):
  File "/home/ubuntu/miniconda3/envs/humanscape/lib/python3.9/site-packages/django/db/backends/utils.py", line 84, in _execute
    return self.cursor.execute(sql, params)
  File "/home/ubuntu/miniconda3/envs/humanscape/lib/python3.9/site-packages/django/db/backends/sqlite3/base.py", line 423, in execute
    return Database.Cursor.execute(self, query, params)
sqlite3.OperationalError: no such table: clinics

The above exception was the direct cause of the following exception:

Traceback (most recent call last):
  File "/home/ubuntu/miniconda3/envs/humanscape/lib/python3.9/site-packages/django/core/handlers/exception.py", line 47, in inner
    response = get_response(request)
  File "/home/ubuntu/miniconda3/envs/humanscape/lib/python3.9/site-packages/django/core/handlers/base.py", line 181, in _get_response
    response = wrapped_callback(request, *callback_args, **callback_kwargs)
  File "/home/ubuntu/miniconda3/envs/humanscape/lib/python3.9/site-packages/django/views/generic/base.py", line 70, in view
    return self.dispatch(request, *args, **kwargs)
  File "/home/ubuntu/miniconda3/envs/humanscape/lib/python3.9/site-packages/django/views/generic/base.py", line 98, in dispatch
    return handler(request, *args, **kwargs)
  File "/home/ubuntu/human-scape-InfinityLoop/clinics/views.py", line 10, in get
    clinic = Clinic.objects.get(id=clinic_id)
  File "/home/ubuntu/miniconda3/envs/humanscape/lib/python3.9/site-packages/django/db/models/manager.py", line 85, in manager_method
    return getattr(self.get_queryset(), name)(*args, **kwargs)
  File "/home/ubuntu/miniconda3/envs/humanscape/lib/python3.9/site-packages/django/db/models/query.py", line 431, in get
    num = len(clone)
  File "/home/ubuntu/miniconda3/envs/humanscape/lib/python3.9/site-packages/django/db/models/query.py", line 262, in __len__
    self._fetch_all()
  File "/home/ubuntu/miniconda3/envs/humanscape/lib/python3.9/site-packages/django/db/models/query.py", line 1324, in _fetch_all
    self._result_cache = list(self._iterable_class(self))
  File "/home/ubuntu/miniconda3/envs/humanscape/lib/python3.9/site-packages/django/db/models/query.py", line 51, in __iter__
    results = compiler.execute_sql(chunked_fetch=self.chunked_fetch, chunk_size=self.chunk_size)
  File "/home/ubuntu/miniconda3/envs/humanscape/lib/python3.9/site-packages/django/db/models/sql/compiler.py", line 1175, in execute_sql
    cursor.execute(sql, params)
  File "/home/ubuntu/miniconda3/envs/humanscape/lib/python3.9/site-packages/django/db/backends/utils.py", line 98, in execute
    return super().execute(sql, params)
  File "/home/ubuntu/miniconda3/envs/humanscape/lib/python3.9/site-packages/django/db/backends/utils.py", line 66, in execute
    return self._execute_with_wrappers(sql, params, many=False, executor=self._execute)
  File "/home/ubuntu/miniconda3/envs/humanscape/lib/python3.9/site-packages/django/db/backends/utils.py", line 75, in _execute_with_wrappers
    return executor(sql, params, many, context)
  File "/home/ubuntu/miniconda3/envs/humanscape/lib/python3.9/site-packages/django/db/backends/utils.py", line 84, in _execute
    return self.cursor.execute(sql, params)
  File "/home/ubuntu/miniconda3/envs/humanscape/lib/python3.9/site-packages/django/db/utils.py", line 90, in __exit__
    raise dj_exc_value.with_traceback(traceback) from exc_value
  File "/home/ubuntu/miniconda3/envs/humanscape/lib/python3.9/site-packages/django/db/backends/utils.py", line 84, in _execute
    return self.cursor.execute(sql, params)
  File "/home/ubuntu/miniconda3/envs/humanscape/lib/python3.9/site-packages/django/db/backends/sqlite3/base.py", line 423, in execute
    return Database.Cursor.execute(self, query, params)
django.db.utils.OperationalError: no such table: clinics
Internal Server Error: /clinics/list
Traceback (most recent call last):
  File "/home/ubuntu/miniconda3/envs/humanscape/lib/python3.9/site-packages/django/db/backends/utils.py", line 84, in _execute
    return self.cursor.execute(sql, params)
  File "/home/ubuntu/miniconda3/envs/humanscape/lib/python3.9/site-packages/django/db/backends/sqlite3/base.py", line 423, in execute
    return Database.Cursor.execute(self, query, params)
sqlite3.OperationalError: no such table: clinics

The above exception was the direct cause of the following exception:

Traceback (most recent call last):
  File "/home/ubuntu/miniconda3/envs/humanscape/lib/python3.9/site-packages/django/core/handlers/exception.py", line 47, in inner
    response = get_response(request)
  File "/home/ubuntu/miniconda3/envs/humanscape/lib/python3.9/site-packages/django/core/handlers/base.py", line 181, in _get_response
    response = wrapped_callback(request, *callback_args, **callback_kwargs)
  File "/home/ubuntu/miniconda3/envs/humanscape/lib/python3.9/site-packages/django/views/generic/base.py", line 70, in view
    return self.dispatch(request, *args, **kwargs)
  File "/home/ubuntu/miniconda3/envs/humanscape/lib/python3.9/site-packages/django/views/generic/base.py", line 98, in dispatch
    return handler(request, *args, **kwargs)
  File "/home/ubuntu/human-scape-InfinityLoop/clinics/views.py", line 40, in get
    "current_count" : len(clinics),
  File "/home/ubuntu/miniconda3/envs/humanscape/lib/python3.9/site-packages/django/db/models/query.py", line 262, in __len__
    self._fetch_all()
  File "/home/ubuntu/miniconda3/envs/humanscape/lib/python3.9/site-packages/django/db/models/query.py", line 1324, in _fetch_all
    self._result_cache = list(self._iterable_class(self))
  File "/home/ubuntu/miniconda3/envs/humanscape/lib/python3.9/site-packages/django/db/models/query.py", line 51, in __iter__
    results = compiler.execute_sql(chunked_fetch=self.chunked_fetch, chunk_size=self.chunk_size)
  File "/home/ubuntu/miniconda3/envs/humanscape/lib/python3.9/site-packages/django/db/models/sql/compiler.py", line 1175, in execute_sql
    cursor.execute(sql, params)
  File "/home/ubuntu/miniconda3/envs/humanscape/lib/python3.9/site-packages/django/db/backends/utils.py", line 98, in execute
    return super().execute(sql, params)
  File "/home/ubuntu/miniconda3/envs/humanscape/lib/python3.9/site-packages/django/db/backends/utils.py", line 66, in execute
    return self._execute_with_wrappers(sql, params, many=False, executor=self._execute)
  File "/home/ubuntu/miniconda3/envs/humanscape/lib/python3.9/site-packages/django/db/backends/utils.py", line 75, in _execute_with_wrappers
    return executor(sql, params, many, context)
  File "/home/ubuntu/miniconda3/envs/humanscape/lib/python3.9/site-packages/django/db/backends/utils.py", line 84, in _execute
    return self.cursor.execute(sql, params)
  File "/home/ubuntu/miniconda3/envs/humanscape/lib/python3.9/site-packages/django/db/utils.py", line 90, in __exit__
    raise dj_exc_value.with_traceback(traceback) from exc_value
  File "/home/ubuntu/miniconda3/envs/humanscape/lib/python3.9/site-packages/django/db/backends/utils.py", line 84, in _execute
    return self.cursor.execute(sql, params)
  File "/home/ubuntu/miniconda3/envs/humanscape/lib/python3.9/site-packages/django/db/backends/sqlite3/base.py", line 423, in execute
    return Database.Cursor.execute(self, query, params)
django.db.utils.OperationalError: no such table: clinics
Internal Server Error: /clinics/1
Traceback (most recent call last):
  File "/home/ubuntu/miniconda3/envs/humanscape/lib/python3.9/site-packages/django/db/backends/utils.py", line 84, in _execute
    return self.cursor.execute(sql, params)
  File "/home/ubuntu/miniconda3/envs/humanscape/lib/python3.9/site-packages/django/db/backends/sqlite3/base.py", line 423, in execute
    return Database.Cursor.execute(self, query, params)
sqlite3.OperationalError: no such table: clinics

The above exception was the direct cause of the following exception:

Traceback (most recent call last):
  File "/home/ubuntu/miniconda3/envs/humanscape/lib/python3.9/site-packages/django/core/handlers/exception.py", line 47, in inner
    response = get_response(request)
  File "/home/ubuntu/miniconda3/envs/humanscape/lib/python3.9/site-packages/django/core/handlers/base.py", line 181, in _get_response
    response = wrapped_callback(request, *callback_args, **callback_kwargs)
  File "/home/ubuntu/miniconda3/envs/humanscape/lib/python3.9/site-packages/django/views/generic/base.py", line 70, in view
    return self.dispatch(request, *args, **kwargs)
  File "/home/ubuntu/miniconda3/envs/humanscape/lib/python3.9/site-packages/django/views/generic/base.py", line 98, in dispatch
    return handler(request, *args, **kwargs)
  File "/home/ubuntu/human-scape-InfinityLoop/clinics/views.py", line 10, in get
    clinic = Clinic.objects.get(id=clinic_id)
  File "/home/ubuntu/miniconda3/envs/humanscape/lib/python3.9/site-packages/django/db/models/manager.py", line 85, in manager_method
    return getattr(self.get_queryset(), name)(*args, **kwargs)
  File "/home/ubuntu/miniconda3/envs/humanscape/lib/python3.9/site-packages/django/db/models/query.py", line 431, in get
    num = len(clone)
  File "/home/ubuntu/miniconda3/envs/humanscape/lib/python3.9/site-packages/django/db/models/query.py", line 262, in __len__
    self._fetch_all()
  File "/home/ubuntu/miniconda3/envs/humanscape/lib/python3.9/site-packages/django/db/models/query.py", line 1324, in _fetch_all
    self._result_cache = list(self._iterable_class(self))
  File "/home/ubuntu/miniconda3/envs/humanscape/lib/python3.9/site-packages/django/db/models/query.py", line 51, in __iter__
    results = compiler.execute_sql(chunked_fetch=self.chunked_fetch, chunk_size=self.chunk_size)
  File "/home/ubuntu/miniconda3/envs/humanscape/lib/python3.9/site-packages/django/db/models/sql/compiler.py", line 1175, in execute_sql
    cursor.execute(sql, params)
  File "/home/ubuntu/miniconda3/envs/humanscape/lib/python3.9/site-packages/django/db/backends/utils.py", line 98, in execute
    return super().execute(sql, params)
  File "/home/ubuntu/miniconda3/envs/humanscape/lib/python3.9/site-packages/django/db/backends/utils.py", line 66, in execute
    return self._execute_with_wrappers(sql, params, many=False, executor=self._execute)
  File "/home/ubuntu/miniconda3/envs/humanscape/lib/python3.9/site-packages/django/db/backends/utils.py", line 75, in _execute_with_wrappers
    return executor(sql, params, many, context)
  File "/home/ubuntu/miniconda3/envs/humanscape/lib/python3.9/site-packages/django/db/backends/utils.py", line 84, in _execute
    return self.cursor.execute(sql, params)
  File "/home/ubuntu/miniconda3/envs/humanscape/lib/python3.9/site-packages/django/db/utils.py", line 90, in __exit__
    raise dj_exc_value.with_traceback(traceback) from exc_value
  File "/home/ubuntu/miniconda3/envs/humanscape/lib/python3.9/site-packages/django/db/backends/utils.py", line 84, in _execute
    return self.cursor.execute(sql, params)
  File "/home/ubuntu/miniconda3/envs/humanscape/lib/python3.9/site-packages/django/db/backends/sqlite3/base.py", line 423, in execute
    return Database.Cursor.execute(self, query, params)
django.db.utils.OperationalError: no such table: clinics
Internal Server Error: /clinics/2
Traceback (most recent call last):
  File "/home/ubuntu/miniconda3/envs/humanscape/lib/python3.9/site-packages/django/db/backends/utils.py", line 84, in _execute
    return self.cursor.execute(sql, params)
  File "/home/ubuntu/miniconda3/envs/humanscape/lib/python3.9/site-packages/django/db/backends/sqlite3/base.py", line 423, in execute
    return Database.Cursor.execute(self, query, params)
sqlite3.OperationalError: no such table: clinics

The above exception was the direct cause of the following exception:

Traceback (most recent call last):
  File "/home/ubuntu/miniconda3/envs/humanscape/lib/python3.9/site-packages/django/core/handlers/exception.py", line 47, in inner
    response = get_response(request)
  File "/home/ubuntu/miniconda3/envs/humanscape/lib/python3.9/site-packages/django/core/handlers/base.py", line 181, in _get_response
    response = wrapped_callback(request, *callback_args, **callback_kwargs)
  File "/home/ubuntu/miniconda3/envs/humanscape/lib/python3.9/site-packages/django/views/generic/base.py", line 70, in view
    return self.dispatch(request, *args, **kwargs)
  File "/home/ubuntu/miniconda3/envs/humanscape/lib/python3.9/site-packages/django/views/generic/base.py", line 98, in dispatch
    return handler(request, *args, **kwargs)
  File "/home/ubuntu/human-scape-InfinityLoop/clinics/views.py", line 10, in get
    clinic = Clinic.objects.get(id=clinic_id)
  File "/home/ubuntu/miniconda3/envs/humanscape/lib/python3.9/site-packages/django/db/models/manager.py", line 85, in manager_method
    return getattr(self.get_queryset(), name)(*args, **kwargs)
  File "/home/ubuntu/miniconda3/envs/humanscape/lib/python3.9/site-packages/django/db/models/query.py", line 431, in get
    num = len(clone)
  File "/home/ubuntu/miniconda3/envs/humanscape/lib/python3.9/site-packages/django/db/models/query.py", line 262, in __len__
    self._fetch_all()
  File "/home/ubuntu/miniconda3/envs/humanscape/lib/python3.9/site-packages/django/db/models/query.py", line 1324, in _fetch_all
    self._result_cache = list(self._iterable_class(self))
  File "/home/ubuntu/miniconda3/envs/humanscape/lib/python3.9/site-packages/django/db/models/query.py", line 51, in __iter__
    results = compiler.execute_sql(chunked_fetch=self.chunked_fetch, chunk_size=self.chunk_size)
  File "/home/ubuntu/miniconda3/envs/humanscape/lib/python3.9/site-packages/django/db/models/sql/compiler.py", line 1175, in execute_sql
    cursor.execute(sql, params)
  File "/home/ubuntu/miniconda3/envs/humanscape/lib/python3.9/site-packages/django/db/backends/utils.py", line 98, in execute
    return super().execute(sql, params)
  File "/home/ubuntu/miniconda3/envs/humanscape/lib/python3.9/site-packages/django/db/backends/utils.py", line 66, in execute
    return self._execute_with_wrappers(sql, params, many=False, executor=self._execute)
  File "/home/ubuntu/miniconda3/envs/humanscape/lib/python3.9/site-packages/django/db/backends/utils.py", line 75, in _execute_with_wrappers
    return executor(sql, params, many, context)
  File "/home/ubuntu/miniconda3/envs/humanscape/lib/python3.9/site-packages/django/db/backends/utils.py", line 84, in _execute
    return self.cursor.execute(sql, params)
  File "/home/ubuntu/miniconda3/envs/humanscape/lib/python3.9/site-packages/django/db/utils.py", line 90, in __exit__
    raise dj_exc_value.with_traceback(traceback) from exc_value
  File "/home/ubuntu/miniconda3/envs/humanscape/lib/python3.9/site-packages/django/db/backends/utils.py", line 84, in _execute
    return self.cursor.execute(sql, params)
  File "/home/ubuntu/miniconda3/envs/humanscape/lib/python3.9/site-packages/django/db/backends/sqlite3/base.py", line 423, in execute
    return Database.Cursor.execute(self, query, params)
django.db.utils.OperationalError: no such table: clinics
Not Found: /clinics/2
Not Found: /clinics/1
Not Found: /clinics/1
Not Found: /clinics/160045
Not Found: /clinics/160045
Not Found: /
